<?xml version="1.0" ?>
<!-- =================================================================================== -->
<!-- |    This document was autogenerated by xacro from bulls.urdf.xacro               | -->
<!-- |    EDITING THIS FILE BY HAND IS NOT RECOMMENDED                                 | -->
<!-- =================================================================================== -->
<robot name="bulls_bot">
  <material name="blue">
    <color rgba="0.0 0.0 0.8 1.0"/>
  </material>
  <material name="red">
    <color rgba="0.8 0.0 0.0 1.0"/>
  </material>
  <material name="green">
    <color rgba="0.0 0.8 0.0 1.0"/>
  </material>
  <material name="dark_grey">
    <color rgba="0.3 0.3 0.3 1.0"/>
  </material>
  <link name="base_link">
    <visual>
      <origin rpy="0 0 0" xyz="0 0 0.3"/>
      <geometry>
        <cylinder length="0.6" radius="0.2"/>
      </geometry>
      <material name="blue"/>
    </visual>
    <collision>
      <origin rpy="0 0 0" xyz="0 0 0.3"/>
      <geometry>
        <cylinder length="0.6" radius="0.2"/>
      </geometry>
    </collision>
  </link>
  <link name="link_1">
    <visual>
      <origin rpy="0 0 0" xyz="0 0 0.2"/>
      <geometry>
        <cylinder length="0.4" radius="0.08"/>
      </geometry>
      <material name="red"/>
    </visual>
    <collision>
      <origin rpy="0 0 0" xyz="0 0 0.2"/>
      <geometry>
        <cylinder length="0.4" radius="0.08"/>
      </geometry>
    </collision>
  </link>
  <link name="link_2">
    <visual>
      <origin rpy="0 0 0" xyz="0 0 0.2"/>
      <geometry>
        <cylinder length="0.4" radius="0.06"/>
      </geometry>
      <material name="green"/>
    </visual>
    <collision>
      <origin rpy="0 0 0" xyz="0 0 0.2"/>
      <geometry>
        <cylinder length="0.4" radius="0.06"/>
      </geometry>
    </collision>
  </link>
  <link name="link_3">
    <visual>
      <origin rpy="0 0 0" xyz="0 0 0.15"/>
      <geometry>
        <cylinder length="0.3" radius="0.05"/>
      </geometry>
      <material name="blue"/>
    </visual>
    <collision>
      <origin rpy="0 0 0" xyz="0 0 0.15"/>
      <geometry>
        <cylinder length="0.3" radius="0.05"/>
      </geometry>
    </collision>
  </link>
  <joint name="arm_0_joint" type="revolute">
    <parent link="base_link"/>
    <child link="link_1"/>
    <origin rpy="0 0 0" xyz="0 0 0.6"/>
    <axis xyz="0 0 1"/>
    <limit effort="10.0" lower="-3.1416" upper="3.1416" velocity="1.0"/>
  </joint>
  <joint name="arm_1_joint" type="revolute">
    <parent link="link_1"/>
    <child link="link_2"/>
    <origin rpy="0 0 0" xyz="0 0 0.4"/>
    <axis xyz="0 1 0"/>
    <limit effort="10.0" lower="-1.5708" upper="1.5708" velocity="1.0"/>
  </joint>
  <joint name="arm_2_joint" type="revolute">
    <parent link="link_2"/>
    <child link="link_3"/>
    <origin rpy="0 0 0" xyz="0 0 0.4"/>
    <axis xyz="0 1 0"/>
    <limit effort="10.0" lower="-2.0" upper="2.0" velocity="1.0"/>
  </joint>
  <joint name="gripper_base_joint" type="fixed">
    <parent link="link_3"/>
    <child link="gripper_base"/>
    <origin rpy="0 0 0" xyz="0 0 0.3"/>
  </joint>
  <link name="gripper_base">
    <visual>
      <origin rpy="0 0 0" xyz="0 0 0.02"/>
      <geometry>
        <box size="0.2 0.04 0.04"/>
      </geometry>
      <material name="dark_grey"/>
    </visual>
    <collision>
      <origin rpy="0 0 0" xyz="0 0 0.02"/>
      <geometry>
        <box size="0.2 0.04 0.04"/>
      </geometry>
    </collision>
  </link>
  <joint name="gripper_finger_joint_1" type="prismatic">
    <parent link="gripper_base"/>
    <child link="left_finger"/>
    <origin rpy="0 0 0" xyz="-0.08 0 0.04"/>
    <axis xyz="1 0 0"/>
    <limit effort="5.0" lower="0.0" upper="0.06" velocity="0.5"/>
  </joint>
  <link name="left_finger">
    <visual>
      <origin rpy="0 0 0" xyz="0 0 0.04"/>
      <geometry>
        <box size="0.02 0.03 0.08"/>
      </geometry>
      <material name="red"/>
    </visual>
    <collision>
      <origin rpy="0 0 0" xyz="0 0 0.04"/>
      <geometry>
        <box size="0.02 0.03 0.08"/>
      </geometry>
    </collision>
  </link>
  <joint name="gripper_finger_joint_2" type="prismatic">
    <parent link="gripper_base"/>
    <child link="right_finger"/>
    <origin rpy="0 0 0" xyz="0.08 0 0.04"/>
    <axis xyz="-1 0 0"/>
    <limit effort="5.0" lower="0.0" upper="0.06" velocity="0.5"/>
  </joint>
  <link name="right_finger">
    <visual>
      <origin rpy="0 0 0" xyz="0 0 0.04"/>
      <geometry>
        <box size="0.02 0.03 0.08"/>
      </geometry>
      <material name="red"/>
    </visual>
    <collision>
      <origin rpy="0 0 0" xyz="0 0 0.04"/>
      <geometry>
        <box size="0.02 0.03 0.08"/>
      </geometry>
    </collision>
  </link>
</robot>
